<?xml version="1.0" ?>
<!-- =================================================================================== -->
<!-- |    This document was autogenerated by xacro from urdf/f450.xacro                | -->
<!-- |    EDITING THIS FILE BY HAND IS NOT RECOMMENDED                                 | -->
<!-- =================================================================================== -->
<robot name="f450">
  <material name="silver">
    <color rgba="0.700 0.700 0.700 1.000"/>
  </material>
  <transmission name="rev_1_tran">
    <type>transmission_interface/SimpleTransmission</type>
    <joint name="rev_1">
      <hardwareInterface>hardware_interface/EffortJointInterface</hardwareInterface>
    </joint>
    <actuator name="rev_1_actr">
      <hardwareInterface>hardware_interface/EffortJointInterface</hardwareInterface>
      <mechanicalReduction>1</mechanicalReduction>
    </actuator>
  </transmission>
  <transmission name="rev_2_tran">
    <type>transmission_interface/SimpleTransmission</type>
    <joint name="rev_2">
      <hardwareInterface>hardware_interface/EffortJointInterface</hardwareInterface>
    </joint>
    <actuator name="rev_2_actr">
      <hardwareInterface>hardware_interface/EffortJointInterface</hardwareInterface>
      <mechanicalReduction>1</mechanicalReduction>
    </actuator>
  </transmission>
  <transmission name="rev_3_tran">
    <type>transmission_interface/SimpleTransmission</type>
    <joint name="rev_3">
      <hardwareInterface>hardware_interface/EffortJointInterface</hardwareInterface>
    </joint>
    <actuator name="rev_3_actr">
      <hardwareInterface>hardware_interface/EffortJointInterface</hardwareInterface>
      <mechanicalReduction>1</mechanicalReduction>
    </actuator>
  </transmission>
  <transmission name="rev_4_tran">
    <type>transmission_interface/SimpleTransmission</type>
    <joint name="rev_4">
      <hardwareInterface>hardware_interface/EffortJointInterface</hardwareInterface>
    </joint>
    <actuator name="rev_4_actr">
      <hardwareInterface>hardware_interface/EffortJointInterface</hardwareInterface>
      <mechanicalReduction>1</mechanicalReduction>
    </actuator>
  </transmission>
  <gazebo reference="base_link">
    <material>Gazebo/Silver</material>
    <mu1>0.2</mu1>
    <mu2>0.2</mu2>
    <self_collide>true</self_collide>
    <gravity>true</gravity>
  </gazebo>
  <gazebo reference="arm_2">
    <material>Gazebo/Silver</material>
    <mu1>0.2</mu1>
    <mu2>0.2</mu2>
    <self_collide>true</self_collide>
  </gazebo>
  <gazebo reference="arm_3">
    <material>Gazebo/Silver</material>
    <mu1>0.2</mu1>
    <mu2>0.2</mu2>
    <self_collide>true</self_collide>
  </gazebo>
  <gazebo reference="arm_4">
    <material>Gazebo/Silver</material>
    <mu1>0.2</mu1>
    <mu2>0.2</mu2>
    <self_collide>true</self_collide>
  </gazebo>
  <gazebo reference="arm_5">
    <material>Gazebo/Silver</material>
    <mu1>0.2</mu1>
    <mu2>0.2</mu2>
    <self_collide>true</self_collide>
  </gazebo>
  <gazebo reference="base_top_v10_1">
    <material>Gazebo/Silver</material>
    <mu1>0.2</mu1>
    <mu2>0.2</mu2>
    <self_collide>true</self_collide>
  </gazebo>
  <gazebo reference="motor_3">
    <material>Gazebo/Silver</material>
    <mu1>0.2</mu1>
    <mu2>0.2</mu2>
    <self_collide>true</self_collide>
  </gazebo>
  <gazebo reference="motor_2">
    <material>Gazebo/Silver</material>
    <mu1>0.2</mu1>
    <mu2>0.2</mu2>
    <self_collide>true</self_collide>
  </gazebo>
  <gazebo reference="motor_4">
    <material>Gazebo/Silver</material>
    <mu1>0.2</mu1>
    <mu2>0.2</mu2>
    <self_collide>true</self_collide>
  </gazebo>
  <gazebo reference="motor_1">
    <material>Gazebo/Silver</material>
    <mu1>0.2</mu1>
    <mu2>0.2</mu2>
    <self_collide>true</self_collide>
  </gazebo>
  <gazebo reference="propellor_1_1">
    <material>Gazebo/Silver</material>
    <mu1>0.2</mu1>
    <mu2>0.2</mu2>
    <self_collide>true</self_collide>
  </gazebo>
  <gazebo reference="propellor_2_2">
    <material>Gazebo/Silver</material>
    <mu1>0.2</mu1>
    <mu2>0.2</mu2>
    <self_collide>true</self_collide>
  </gazebo>
  <gazebo reference="propellor_1_2">
    <material>Gazebo/Silver</material>
    <mu1>0.2</mu1>
    <mu2>0.2</mu2>
    <self_collide>true</self_collide>
  </gazebo>
  <gazebo reference="propellor_2_1">
    <material>Gazebo/Silver</material>
    <mu1>0.2</mu1>
    <mu2>0.2</mu2>
    <self_collide>true</self_collide>
  </gazebo>
  <gazebo reference="base_lidar_1">
    <material>Gazebo/Silver</material>
    <mu1>0.2</mu1>
    <mu2>0.2</mu2>
    <self_collide>true</self_collide>
  </gazebo>
  <gazebo reference="lidar_1">
    <material>Gazebo/Silver</material>
    <mu1>0.2</mu1>
    <mu2>0.2</mu2>
    <self_collide>true</self_collide>
  </gazebo>
  <link name="base_link">
    <inertial>
      <origin rpy="0 0 0" xyz="-0.0001563325677159355 0.0019454641708941268 0.008011884215420224"/>
      <mass value="0.16180101306018108"/>
      <inertia ixx="0.000236" ixy="-0.000106" ixz="-1e-06" iyy="0.000237" iyz="-0.0" izz="0.000474"/>
    </inertial>
    <visual>
      <origin rpy="0 0 0" xyz="0 0 0"/>
      <geometry>
        <mesh filename="file:///home/dave/ros2_ws/install/f450_description/share/f450_description/meshes/base_link.stl" scale="0.001 0.001 0.001"/>
      </geometry>
      <material name="silver"/>
    </visual>
    <collision>
      <origin rpy="0 0 0" xyz="0 0 0"/>
      <geometry>
        <mesh filename="file:///home/dave/ros2_ws/install/f450_description/share/f450_description/meshes/base_link.stl" scale="0.001 0.001 0.001"/>
      </geometry>
    </collision>
    <enable_wind>1</enable_wind>
  </link>
  <link name="arm_2">
    <inertial>
      <origin rpy="0 0 0" xyz="0.068360672390792 0.010577406778874534 0.029122685883939594"/>
      <mass value="0.19520309289922932"/>
      <inertia ixx="3.8e-05" ixy="3e-06" ixz="1.6e-05" iyy="0.000921" iyz="-0.0" izz="0.000922"/>
    </inertial>
    <visual>
      <origin rpy="0 0 0" xyz="-0.056192 0.009351 -0.008919"/>
      <geometry>
        <mesh filename="file:///home/dave/ros2_ws/install/f450_description/share/f450_description/meshes/arm_2.stl" scale="0.001 0.001 0.001"/>
      </geometry>
      <material name="silver"/>
    </visual>
    <collision>
      <origin rpy="0 0 0" xyz="-0.056192 0.009351 -0.008919"/>
      <geometry>
        <mesh filename="file:///home/dave/ros2_ws/install/f450_description/share/f450_description/meshes/arm_2.stl" scale="0.001 0.001 0.001"/>
      </geometry>
    </collision>
    <enable_wind>1</enable_wind>
  </link>
  <link name="arm_3">
    <inertial>
      <origin rpy="0 0 0" xyz="-0.06848042265090791 -0.010621388792636521 0.02882417021128861"/>
      <mass value="0.19520309289922932"/>
      <inertia ixx="3.8e-05" ixy="3e-06" ixz="-1.9e-05" iyy="0.000921" iyz="0.0" izz="0.000922"/>
    </inertial>
    <visual>
      <origin rpy="0 0 0" xyz="0.0566 -0.013243 -0.008704"/>
      <geometry>
        <mesh filename="file:///home/dave/ros2_ws/install/f450_description/share/f450_description/meshes/arm_3.stl" scale="0.001 0.001 0.001"/>
      </geometry>
      <material name="silver"/>
    </visual>
    <collision>
      <origin rpy="0 0 0" xyz="0.0566 -0.013243 -0.008704"/>
      <geometry>
        <mesh filename="file:///home/dave/ros2_ws/install/f450_description/share/f450_description/meshes/arm_3.stl" scale="0.001 0.001 0.001"/>
      </geometry>
    </collision>
    <enable_wind>1</enable_wind>
  </link>
  <link name="arm_4">
    <inertial>
      <origin rpy="0 0 0" xyz="-0.011100166262585937 -0.06837613208364918 0.02889807701551922"/>
      <mass value="0.19520309289922932"/>
      <inertia ixx="0.000921" ixy="-3e-06" ixz="-0.0" iyy="3.8e-05" iyz="-1.8e-05" izz="0.000922"/>
    </inertial>
    <visual>
      <origin rpy="0 0 0" xyz="-0.010757 0.054516 -0.008792"/>
      <geometry>
        <mesh filename="file:///home/dave/ros2_ws/install/f450_description/share/f450_description/meshes/arm_4.stl" scale="0.001 0.001 0.001"/>
      </geometry>
      <material name="silver"/>
    </visual>
    <collision>
      <origin rpy="0 0 0" xyz="-0.010757 0.054516 -0.008792"/>
      <geometry>
        <mesh filename="file:///home/dave/ros2_ws/install/f450_description/share/f450_description/meshes/arm_4.stl" scale="0.001 0.001 0.001"/>
      </geometry>
    </collision>
    <enable_wind>1</enable_wind>
  </link>
  <link name="arm_5">
    <inertial>
      <origin rpy="0 0 0" xyz="-0.010658560534006191 0.06839888433381819 0.029003407517424702"/>
      <mass value="0.19520309289922932"/>
      <inertia ixx="0.000921" ixy="-3e-06" ixz="0.0" iyy="3.8e-05" iyz="1.7e-05" izz="0.000922"/>
    </inertial>
    <visual>
      <origin rpy="0 0 0" xyz="-0.009314 -0.058367 -0.008874"/>
      <geometry>
        <mesh filename="file:///home/dave/ros2_ws/install/f450_description/share/f450_description/meshes/arm_5.stl" scale="0.001 0.001 0.001"/>
      </geometry>
      <material name="silver"/>
    </visual>
    <collision>
      <origin rpy="0 0 0" xyz="-0.009314 -0.058367 -0.008874"/>
      <geometry>
        <mesh filename="file:///home/dave/ros2_ws/install/f450_description/share/f450_description/meshes/arm_5.stl" scale="0.001 0.001 0.001"/>
      </geometry>
    </collision>
    <enable_wind>1</enable_wind>
  </link>
  <link name="base_top_v10_1">
    <inertial>
      <origin rpy="0 0 0" xyz="-0.06251189150838855 -0.0010219774903443958 0.0006700984655056488"/>
      <mass value="0.1026092055375283"/>
      <inertia ixx="9.2e-05" ixy="-3e-06" ixz="-0.0" iyy="9.2e-05" iyz="-0.0" izz="0.000184"/>
    </inertial>
    <visual>
      <origin rpy="0 0 0" xyz="-0.061525 -0.001423 -0.047939"/>
      <geometry>
        <mesh filename="file:///home/dave/ros2_ws/install/f450_description/share/f450_description/meshes/base_top_v10_1.stl" scale="0.001 0.001 0.001"/>
      </geometry>
      <material name="silver"/>
    </visual>
    <collision>
      <origin rpy="0 0 0" xyz="-0.061525 -0.001423 -0.047939"/>
      <geometry>
        <mesh filename="file:///home/dave/ros2_ws/install/f450_description/share/f450_description/meshes/base_top_v10_1.stl" scale="0.001 0.001 0.001"/>
      </geometry>
    </collision>
    <enable_wind>1</enable_wind>
  </link>
  <link name="motor_3">
    <inertial>
      <origin rpy="0 0 0" xyz="-3.09526771888613e-05 -1.1568468838710037e-05 0.014843253589676232"/>
      <mass value="0.08230746374848247"/>
      <inertia ixx="1.2e-05" ixy="-0.0" ixz="0.0" iyy="1.2e-05" iyz="0.0" izz="1.2e-05"/>
    </inertial>
    <visual>
      <origin rpy="0 0 0" xyz="0.22656 -0.002921 -0.043096"/>
      <geometry>
        <mesh filename="file:///home/dave/ros2_ws/install/f450_description/share/f450_description/meshes/motor_3.stl" scale="0.001 0.001 0.001"/>
      </geometry>
      <material name="silver"/>
    </visual>
    <collision>
      <origin rpy="0 0 0" xyz="0.22656 -0.002921 -0.043096"/>
      <geometry>
        <mesh filename="file:///home/dave/ros2_ws/install/f450_description/share/f450_description/meshes/motor_3.stl" scale="0.001 0.001 0.001"/>
      </geometry>
    </collision>
    <enable_wind>1</enable_wind>
  </link>
  <link name="motor_2">
    <inertial>
      <origin rpy="0 0 0" xyz="-3.097451546599987e-05 -1.0986214982688924e-05 0.014843487748542085"/>
      <mass value="0.08230746374848247"/>
      <inertia ixx="1.2e-05" ixy="-0.0" ixz="0.0" iyy="1.2e-05" iyz="0.0" izz="1.2e-05"/>
    </inertial>
    <visual>
      <origin rpy="0 0 0" xyz="0.000658 0.224365 -0.043389"/>
      <geometry>
        <mesh filename="file:///home/dave/ros2_ws/install/f450_description/share/f450_description/meshes/motor_2.stl" scale="0.001 0.001 0.001"/>
      </geometry>
      <material name="silver"/>
    </visual>
    <collision>
      <origin rpy="0 0 0" xyz="0.000658 0.224365 -0.043389"/>
      <geometry>
        <mesh filename="file:///home/dave/ros2_ws/install/f450_description/share/f450_description/meshes/motor_2.stl" scale="0.001 0.001 0.001"/>
      </geometry>
    </collision>
    <enable_wind>1</enable_wind>
  </link>
  <link name="motor_4">
    <inertial>
      <origin rpy="0 0 0" xyz="-3.0806533986266205e-05 -1.1698907832526583e-05 0.014843625309392629"/>
      <mass value="0.08230746374848247"/>
      <inertia ixx="1.2e-05" ixy="-0.0" ixz="0.0" iyy="1.2e-05" iyz="0.0" izz="1.2e-05"/>
    </inertial>
    <visual>
      <origin rpy="0 0 0" xyz="-0.226009 -0.000919 -0.044027"/>
      <geometry>
        <mesh filename="file:///home/dave/ros2_ws/install/f450_description/share/f450_description/meshes/motor_4.stl" scale="0.001 0.001 0.001"/>
      </geometry>
      <material name="silver"/>
    </visual>
    <collision>
      <origin rpy="0 0 0" xyz="-0.226009 -0.000919 -0.044027"/>
      <geometry>
        <mesh filename="file:///home/dave/ros2_ws/install/f450_description/share/f450_description/meshes/motor_4.stl" scale="0.001 0.001 0.001"/>
      </geometry>
    </collision>
    <enable_wind>1</enable_wind>
  </link>
  <link name="motor_1">
    <inertial>
      <origin rpy="0 0 0" xyz="-3.0761232185650507e-05 -1.1546897757841457e-05 0.014843019588242544"/>
      <mass value="0.08230746374848247"/>
      <inertia ixx="1.2e-05" ixy="-0.0" ixz="0.0" iyy="1.2e-05" iyz="0.0" izz="1.2e-05"/>
    </inertial>
    <visual>
      <origin rpy="0 0 0" xyz="0.001053 -0.22823 -0.043732"/>
      <geometry>
        <mesh filename="file:///home/dave/ros2_ws/install/f450_description/share/f450_description/meshes/motor_1.stl" scale="0.001 0.001 0.001"/>
      </geometry>
      <material name="silver"/>
    </visual>
    <collision>
      <origin rpy="0 0 0" xyz="0.001053 -0.22823 -0.043732"/>
      <geometry>
        <mesh filename="file:///home/dave/ros2_ws/install/f450_description/share/f450_description/meshes/motor_1.stl" scale="0.001 0.001 0.001"/>
      </geometry>
    </collision>
    <enable_wind>1</enable_wind>
  </link>
  <link name="propellor_1_1">
    <inertial>
      <origin rpy="0 0 0" xyz="-2.1203933977420597e-05 -5.4492414743503165e-06 0.006659753036161328"/>
      <mass value="0.04596832624465719"/>
      <inertia ixx="2e-06" ixy="1e-06" ixz="-0.0" iyy="0.000173" iyz="0.0" izz="0.000173"/>
    </inertial>
    <visual>
      <origin rpy="0 0 0" xyz="0.226624 -0.002897 -0.074096"/>
      <geometry>
        <mesh filename="file:///home/dave/ros2_ws/install/f450_description/share/f450_description/meshes/propellor_1_1.stl" scale="0.001 0.001 0.001"/>
      </geometry>
      <material name="silver"/>
    </visual>
    <collision>
      <origin rpy="0 0 0" xyz="0.226624 -0.002897 -0.074096"/>
      <geometry>
        <mesh filename="file:///home/dave/ros2_ws/install/f450_description/share/f450_description/meshes/propellor_1_1.stl" scale="0.001 0.001 0.001"/>
      </geometry>
    </collision>
    <enable_wind>1</enable_wind>
  </link>
  <link name="propellor_2_2">
    <inertial>
      <origin rpy="0 0 0" xyz="-2.0559666656236363e-05 -8.775987938303142e-07 0.010182800691096797"/>
      <mass value="0.04864675101365255"/>
      <inertia ixx="0.000173" ixy="-0.0" ixz="0.0" iyy="2e-06" iyz="-0.0" izz="0.000173"/>
    </inertial>
    <visual>
      <origin rpy="0 0 0" xyz="0.001117 -0.228206 -0.074732"/>
      <geometry>
        <mesh filename="file:///home/dave/ros2_ws/install/f450_description/share/f450_description/meshes/propellor_2_2.stl" scale="0.001 0.001 0.001"/>
      </geometry>
      <material name="silver"/>
    </visual>
    <collision>
      <origin rpy="0 0 0" xyz="0.001117 -0.228206 -0.074732"/>
      <geometry>
        <mesh filename="file:///home/dave/ros2_ws/install/f450_description/share/f450_description/meshes/propellor_2_2.stl" scale="0.001 0.001 0.001"/>
      </geometry>
    </collision>
    <enable_wind>1</enable_wind>
  </link>
  <link name="propellor_1_2">
    <inertial>
      <origin rpy="0 0 0" xyz="-1.3434893079237076e-05 -1.2514295851306922e-05 0.006659998211777041"/>
      <mass value="0.04596832624465719"/>
      <inertia ixx="0.000173" ixy="-1e-06" ixz="-0.0" iyy="2e-06" iyz="-0.0" izz="0.000173"/>
    </inertial>
    <visual>
      <origin rpy="0 0 0" xyz="0.000722 0.224388 -0.074389"/>
      <geometry>
        <mesh filename="file:///home/dave/ros2_ws/install/f450_description/share/f450_description/meshes/propellor_1_2.stl" scale="0.001 0.001 0.001"/>
      </geometry>
      <material name="silver"/>
    </visual>
    <collision>
      <origin rpy="0 0 0" xyz="0.000722 0.224388 -0.074389"/>
      <geometry>
        <mesh filename="file:///home/dave/ros2_ws/install/f450_description/share/f450_description/meshes/propellor_1_2.stl" scale="0.001 0.001 0.001"/>
      </geometry>
    </collision>
    <enable_wind>1</enable_wind>
  </link>
  <link name="propellor_2_1">
    <inertial>
      <origin rpy="0 0 0" xyz="-2.0604968456766626e-05 -1.0296088685228131e-06 0.010183406412246923"/>
      <mass value="0.04864675101365255"/>
      <inertia ixx="0.000173" ixy="-0.0" ixz="0.0" iyy="2e-06" iyz="-0.0" izz="0.000173"/>
    </inertial>
    <visual>
      <origin rpy="0 0 0" xyz="-0.225945 -0.000895 -0.075027"/>
      <geometry>
        <mesh filename="file:///home/dave/ros2_ws/install/f450_description/share/f450_description/meshes/propellor_2_1.stl" scale="0.001 0.001 0.001"/>
      </geometry>
      <material name="silver"/>
    </visual>
    <collision>
      <origin rpy="0 0 0" xyz="-0.225945 -0.000895 -0.075027"/>
      <geometry>
        <mesh filename="file:///home/dave/ros2_ws/install/f450_description/share/f450_description/meshes/propellor_2_1.stl" scale="0.001 0.001 0.001"/>
      </geometry>
    </collision>
    <enable_wind>1</enable_wind>
  </link>
  <link name="base_lidar_1">
    <inertial>
      <origin rpy="0 0 0" xyz="-0.00494482579743611 -0.004877772771115618 0.029374053893343945"/>
      <mass value="0.03529800000000004"/>
      <inertia ixx="3.4e-05" ixy="7e-06" ixz="-3e-06" iyy="3.4e-05" iyz="-3e-06" izz="2e-05"/>
    </inertial>
    <visual>
      <origin rpy="0 0 0" xyz="-0.064333 -0.066101 -0.008993"/>
      <geometry>
        <mesh filename="file:///home/dave/ros2_ws/install/f450_description/share/f450_description/meshes/base_lidar_1.stl" scale="0.001 0.001 0.001"/>
      </geometry>
      <material name="silver"/>
    </visual>
    <collision>
      <origin rpy="0 0 0" xyz="-0.064333 -0.066101 -0.008993"/>
      <geometry>
        <mesh filename="file:///home/dave/ros2_ws/install/f450_description/share/f450_description/meshes/base_lidar_1.stl" scale="0.001 0.001 0.001"/>
      </geometry>
    </collision>
    <enable_wind>1</enable_wind>
  </link>
  <link name="lidar_1">
    <inertial>
      <origin rpy="0 0 0" xyz="0.020600379902440832 0.020478289994783946 5.8392732863232766e-05"/>
      <mass value="0.213"/>
      <inertia ixx="0.000267" ixy="2.1e-05" ixz="-0.0" iyy="0.000266" iyz="0.0" izz="0.000289"/>
    </inertial>
    <visual>
      <origin rpy="0 0 0" xyz="-0.064251 -0.066071 -0.048993"/>
      <geometry>
        <mesh filename="file:///home/dave/ros2_ws/install/f450_description/share/f450_description/meshes/lidar_1.stl" scale="0.001 0.001 0.001"/>
      </geometry>
      <material name="silver"/>
    </visual>
    <collision>
      <origin rpy="0 0 0" xyz="-0.064251 -0.066071 -0.048993"/>
      <geometry>
        <mesh filename="file:///home/dave/ros2_ws/install/f450_description/share/f450_description/meshes/lidar_1.stl" scale="0.001 0.001 0.001"/>
      </geometry>
    </collision>
    <enable_wind>1</enable_wind>
  </link>
  <gazebo reference="lidar_1">
    <sensor name="lidar_sensor" type="gpu_lidar">
      <pose relative_to="lidar_1">0 0 0 0 0 0</pose>
      <update_rate>30</update_rate>
      <topic>lidar</topic>
      <ray>
        <scan>
          <horizontal>
            <samples>720</samples>
            <resolution>1</resolution>
            <min_angle>-3.14</min_angle>
            <max_angle>3.14</max_angle>
          </horizontal>
          <vertical>
            <samples>1</samples>
            <resolution>1</resolution>
            <min_angle>0.0</min_angle>
            <max_angle>0.0</max_angle>
          </vertical>
        </scan>
        <range>
          <min>0.1</min>
          <max>40.0</max>
          <resolution>0.01</resolution>
        </range>
        <noise>
          <type>gaussian</type>
          <mean>0.0</mean>
          <stddev>0.01</stddev>
        </noise>
      </ray>
      <always_on>1</always_on>
      <visualize>true</visualize>
    </sensor>
  </gazebo>
  <!-- Link del IMU -->
  <link name="imu_link">
    <inertial>
      <origin rpy="0 0 0" xyz="0 0 0"/>
      <mass value="0.01"/>
      <inertia ixx="1e-6" ixy="0" ixz="0" iyy="1e-6" iyz="0" izz="1e-6"/>
    </inertial>
    <visual>
      <origin rpy="0 0 0" xyz="0 0 0"/>
      <geometry>
        <box size="0.01 0.01 0.01"/>
      </geometry>
      <material name="silver"/>
    </visual>
    <collision>
      <origin rpy="0 0 0" xyz="0 0 0"/>
      <geometry>
        <box size="0.01 0.01 0.01"/>
      </geometry>
    </collision>
  </link>
  <!-- Unión del IMU al cuerpo principal -->
  <joint name="imu_joint" type="fixed">
    <parent link="base_link"/>
    <child link="imu_link"/>
    <origin rpy="0 0 0" xyz="0 0 0.02"/>
  </joint>
  <!-- Definición del sensor IMU con plugin para Gazebo -->
  <gazebo reference="imu_link">
    <sensor name="imu_sensor" type="imu">
      <pose>0 0 0 0 0 0</pose>
      <always_on>true</always_on>
      <update_rate>100</update_rate>
      <visualize>false</visualize>
      <topic>imu</topic>
      <plugin filename="gz-sim-imu-system" name="gz::sim::systems::Imu"/>
    </sensor>
  </gazebo>
  <joint name="r_1" type="fixed">
    <origin rpy="0 0 0" xyz="0.056192 -0.009351 0.008919"/>
    <parent link="base_link"/>
    <child link="arm_2"/>
  </joint>
  <joint name="r_2" type="fixed">
    <origin rpy="0 0 0" xyz="-0.0566 0.013243 0.008704"/>
    <parent link="base_link"/>
    <child link="arm_3"/>
  </joint>
  <joint name="r_3" type="fixed">
    <origin rpy="0 0 0" xyz="0.010757 -0.054516 0.008792"/>
    <parent link="base_link"/>
    <child link="arm_4"/>
  </joint>
  <joint name="r_4" type="fixed">
    <origin rpy="0 0 0" xyz="0.009314 0.058367 0.008874"/>
    <parent link="base_link"/>
    <child link="arm_5"/>
  </joint>
  <joint name="r_5" type="fixed">
    <origin rpy="0 0 0" xyz="0.005333 0.010774 0.03902"/>
    <parent link="arm_2"/>
    <child link="base_top_v10_1"/>
  </joint>
  <joint name="r_8" type="fixed">
    <origin rpy="0 0 0" xyz="-0.16996 -0.010322 0.034392"/>
    <parent link="arm_3"/>
    <child link="motor_3"/>
  </joint>
  <joint name="r_9" type="fixed">
    <origin rpy="0 0 0" xyz="-0.011415 -0.169849 0.034597"/>
    <parent link="arm_4"/>
    <child link="motor_2"/>
  </joint>
  <joint name="r_10" type="fixed">
    <origin rpy="0 0 0" xyz="0.169817 0.01027 0.035108"/>
    <parent link="arm_2"/>
    <child link="motor_4"/>
  </joint>
  <joint name="r_11" type="fixed">
    <origin rpy="0 0 0" xyz="-0.010367 0.169863 0.034858"/>
    <parent link="arm_5"/>
    <child link="motor_1"/>
  </joint>
  <joint name="rev_1" type="continuous">
    <origin rpy="0 0 0" xyz="-6.4e-05 -2.4e-05 0.031"/>
    <parent link="motor_3"/>
    <child link="propellor_1_1"/>
    <axis xyz="0.002061 0.000759 -0.999998"/>
  </joint>
  <joint name="rev_2" type="continuous">
    <origin rpy="0 0 0" xyz="-6.4e-05 -2.4e-05 0.031"/>
    <parent link="motor_1"/>
    <child link="propellor_2_2"/>
    <axis xyz="0.002061 0.000759 -0.999998"/>
  </joint>
  <joint name="rev_3" type="continuous">
    <origin rpy="0 0 0" xyz="-6.4e-05 -2.3e-05 0.031"/>
    <parent link="motor_2"/>
    <child link="propellor_1_2"/>
    <axis xyz="0.002061 0.000759 -0.999998"/>
  </joint>
  <joint name="rev_4" type="continuous">
    <origin rpy="0 0 0" xyz="-6.4e-05 -2.4e-05 0.031"/>
    <parent link="motor_4"/>
    <child link="propellor_2_1"/>
    <axis xyz="0.002061 0.000759 -0.999998"/>
  </joint>
  <joint name="r_12" type="fixed">
    <origin rpy="0 0 0" xyz="0.064333 0.066101 0.008993"/>
    <parent link="base_link"/>
    <child link="base_lidar_1"/>
  </joint>
  <joint name="r_13" type="fixed">
    <origin rpy="0 0 0" xyz="-8.2e-05 -3e-05 0.04"/>
    <parent link="base_lidar_1"/>
    <child link="lidar_1"/>
  </joint>
  <gazebo>
    <plugin filename="gz-sim-multicopter-motor-model-system" name="gz::sim::systems::MulticopterMotorModel">
      <robotNamespace>f450</robotNamespace>
      <jointName>rev_1</jointName>
      <linkName>propellor_1_1</linkName>
      <turningDirection>ccw</turningDirection>
      <timeConstantUp>0.0125</timeConstantUp>
      <timeConstantDown>0.025</timeConstantDown>
      <maxRotVelocity>5000.0</maxRotVelocity>
      <motorConstant>8.54858e-06</motorConstant>
      <momentConstant>0.016</momentConstant>
      <commandSubTopic>gazebo/command/motor_speed</commandSubTopic>
      <actuator_number>0</actuator_number>
      <rotorDragCoefficient>8.06428e-05</rotorDragCoefficient>
      <rollingMomentCoefficient>1e-06</rollingMomentCoefficient>
      <motorSpeedPubTopic>motor_speed/0</motorSpeedPubTopic>
      <rotorVelocitySlowdownSim>10</rotorVelocitySlowdownSim>
      <motorType>velocity</motorType>
    </plugin>
    <plugin filename="gz-sim-multicopter-motor-model-system" name="gz::sim::systems::MulticopterMotorModel">
      <robotNamespace>f450</robotNamespace>
      <jointName>rev_2</jointName>
      <linkName>propellor_1_2</linkName>
      <turningDirection>cw</turningDirection>
      <timeConstantUp>0.0125</timeConstantUp>
      <timeConstantDown>0.025</timeConstantDown>
      <maxRotVelocity>5000.0</maxRotVelocity>
      <motorConstant>8.54858e-06</motorConstant>
      <momentConstant>0.016</momentConstant>
      <commandSubTopic>gazebo/command/motor_speed</commandSubTopic>
      <actuator_number>1</actuator_number>
      <rotorDragCoefficient>8.06428e-05</rotorDragCoefficient>
      <rollingMomentCoefficient>1e-06</rollingMomentCoefficient>
      <motorSpeedPubTopic>motor_speed/1</motorSpeedPubTopic>
      <rotorVelocitySlowdownSim>10</rotorVelocitySlowdownSim>
      <motorType>velocity</motorType>
    </plugin>
    <plugin filename="gz-sim-multicopter-motor-model-system" name="gz::sim::systems::MulticopterMotorModel">
      <robotNamespace>f450</robotNamespace>
      <jointName>rev_3</jointName>
      <linkName>propellor_2_1</linkName>
      <turningDirection>ccw</turningDirection>
      <timeConstantUp>0.0125</timeConstantUp>
      <timeConstantDown>0.025</timeConstantDown>
      <maxRotVelocity>5000.0</maxRotVelocity>
      <motorConstant>8.54858e-06</motorConstant>
      <momentConstant>0.016</momentConstant>
      <commandSubTopic>gazebo/command/motor_speed</commandSubTopic>
      <actuator_number>2</actuator_number>
      <rotorDragCoefficient>8.06428e-05</rotorDragCoefficient>
      <rollingMomentCoefficient>1e-06</rollingMomentCoefficient>
      <motorSpeedPubTopic>motor_speed/2</motorSpeedPubTopic>
      <rotorVelocitySlowdownSim>10</rotorVelocitySlowdownSim>
      <motorType>velocity</motorType>
    </plugin>
    <plugin filename="gz-sim-multicopter-motor-model-system" name="gz::sim::systems::MulticopterMotorModel">
      <robotNamespace>f450</robotNamespace>
      <jointName>rev_4</jointName>
      <linkName>propellor_2_2</linkName>
      <turningDirection>cw</turningDirection>
      <timeConstantUp>0.0125</timeConstantUp>
      <timeConstantDown>0.025</timeConstantDown>
      <maxRotVelocity>5000.0</maxRotVelocity>
      <motorConstant>8.54858e-06</motorConstant>
      <momentConstant>0.016</momentConstant>
      <commandSubTopic>gazebo/command/motor_speed</commandSubTopic>
      <actuator_number>3</actuator_number>
      <rotorDragCoefficient>8.06428e-05</rotorDragCoefficient>
      <rollingMomentCoefficient>1e-06</rollingMomentCoefficient>
      <motorSpeedPubTopic>motor_speed/3</motorSpeedPubTopic>
      <rotorVelocitySlowdownSim>10</rotorVelocitySlowdownSim>
      <motorType>velocity</motorType>
    </plugin>
  </gazebo>
</robot>
